Workbook

Sheet Stack Test jul062018
A1: Spear 2 Crowbar Stack Testing | C1: Test Date: 7/28/2018
A3: Stacks removed July 06, 2018
A5: All data @ 30 minutes | B5: LC @ 25KV | C5: Temps | D5: Overvolts | E5: Light
A6: HV applied | B6: mA | C6: Deg. C | D6: Self-Fire KV | E6: Trigger
C7: Time= 30 mins | D7: Pass/Fail | E7: Pass/Fail
A9: Crowbar 1 | B9: 0.891+ | C9: 28.2-32.4 | D9: P43.3KV | E9: Pass
A11: Crowbar 2 | B11: 0.862 | C11: 28.4-35.2 | D11: P 42.8KV | E11: Pass
A13: Crowbar 3 | B13: 0.888 | C13: 29.1-35.6 | D13: P43.25KV | E13: Pass
A15: Crowbar 4 | B15: 0.911+ | C15: 28.2-37.9 | D15: P 43.4KV | E15: Pass
A17: All 4 stacks removed from Spear 2 RF HVPS on July 6, 2018
A20: Conclusions: Stack 4 has high leakage current (nominal should be < .890 mA) and is likely a culprit in sagging output volts. Stack 1 leakage current creaping upward slowly and is marginal. Stacks 2+3 appear to be good: leakage current was steady over 1/2 hour test period.

Sheet Stack Test jul072018
A1: Spear 2 Crowbar Stack Testing | C1: Test Date: 8/4/2018
A3: Stacks removed from Spear 2 August 03, 2018
A5: All data @ 30 minutes | B5: LC @ 25KV | D5: Overvolts | E5: Light
A6: HV applied | B6: mA | D6: Self-Fire KV | E6: Trigger
D7: Pass/Fail | E7: Pass/Fail
A9: Crowbar 1 | B9: 0.857 | C9: 1.12 mA | D9: Failed @ 43KV | E9: Pass
A11: Crowbar 2 | B11: 0.891 | D11: Pass @ 43.55KV | E11: Pass
A13: Crowbar 3 | B13: 0.861 | D13: Pass @ 44.2 KV | E13: Pass
A15: Crowbar 4 | B15: 0.887 | D15: Pass @ 43.05 | E15: Pass
A18: Conclusions: Stack 1 functioned normally with good, stable leakage current. One SCR (#3 in stack 1) failed with self-fire @ 43 KV. The stack was good during ops. It is not normal for a stack to self-fire--the crowbar ckt operates with a trigger pulse. Leakage after failed SCR was 1.1 mA and stable @ 25KV. The other 5 SCRs in the stack are good. Stack 2 leakage @ 30 minutes was a little high, but appears to function correctly. Stacks 3+4 are good with stable leakage current @ 25 KVDC. It's possible over a longer operational period at higher temperatures in the crowbar tank than in free air the stacks started to partially self-fire (possibly stack 2). But from the uncertainty of this limited testing, it is warranted to test the main tank rectifiers and filter circuits and to replace the main tank rectifiers and filter caps and to perform a thorough inspection of wiring and bushings.

Sheet Operational Data
A1: Spear 2 RF HVPS Individual SCR Tests | F1: 43320 | L1: Spear 2 RF HVPS Individual SCR Tests | Q1: 43327
A3: Set 2 Crowbar Stacks removed 3 August 2018 (failed 7 July 2018) | L3: Set 1 Crowbar Stacks removed 6 July 2018 (failed July 6 2018)
B6: SCR # | C6: Serial # | D6: uA @ 4.2 KV | E6: uA @ 6.5KV | F6: F.O. Trigs | G6: OV Self-Fire | H6: Creeping Up | I6: Re-Use? | M6: SCR # | N6: Serial # | O6: uA @ 4.2 KV | P6: uA @ 6.5KV | Q6: F.O. Trigs | R6: OV Self-Fire | S6: Creeping Up | T6: Re-Use? | AF6: Copied data for histograms (do not know how to histogram data from different columns)
AF7: 4.2 kV | AG7: 6.5 kV | AH7: SelfFIre
A8: Stack 1 | B8: 1 | C8: 2436 | D8: 10.1 | E8: 17.7 | F8: Good | G8: 7.7 | H8: N | I8: Yes | L8: Stack 1 | M8: 1 | N8: 2326 | O8: 154.2 | P8: 495 | Q8: Good | R8: 7.35 | S8: Y | T8: No | AF8: =D8 -> 10.1 | AG8: =E8 -> 17.7 | AH8: =G8 -> 7.7
B9: 2 | C9: 2364 | D9: 28.8 | E9: 49.2 | F9: Good | G9: 7.3 | H9: N | I9: Yes | M9: 2 | N9: 2322 | O9: 34.6 | P9: 71 | Q9: Good | R9: 7.8 | S9: N | T9: Yes | AF9: =D9 -> 28.8 | AG9: =E9 -> 49.2 | AH9: =G9 -> 7.3
B10: 3 | C10: 2362 | D10: 23.4 | E10: 64.2 | F10: Good | G10: 0 | H10: N | I10: No | M10: 3 | N10: 2319 | O10: 20.5 | P10: 43 | Q10: Good | R10: 0 | S10: N | T10: No | AF10: =D10 -> 23.4 | AG10: =E10 -> 64.2 | AH10: =G10 -> 0
B11: 4 | C11: 2357 | D11: 25.5 | E11: 42.4 | F11: Good | G11: 7.3 | H11: N | I11: Yes | M11: 4 | N11: 2428 | O11: 81.6 | P11: 143.5 | Q11: Good | R11: 7.8 | S11: Y | T11: No | AF11: =D11 -> 25.5 | AG11: =E11 -> 42.4 | AH11: =G11 -> 7.3
B12: 5 | C12: 2361 | D12: 11.6 | E12: 21.5 | F12: Good | G12: 7.2 | H12: N | I12: Yes | M12: 5 | N12: 2429 | O12: 99.3 | P12: 276.5 | Q12: Good | R12: 7.4 | S12: Y | T12: No | AF12: =D12 -> 11.6 | AG12: =E12 -> 21.5 | AH12: =G12 -> 7.2
B13: 6 | C13: 5636 | D13: 57.4 | E13: 94.2 | F13: Good | G13: 7.5 | H13: Y | I13: No | M13: 6 | N13: 2350 | O13: 9.3 | P13: 24.7 | Q13: Good | R13: 7.5 | S13: N | T13: Yes | AF13: =D13 -> 57.4 | AG13: =E13 -> 94.2 | AH13: =G13 -> 7.5
A14: Stack 2 | B14: 1 | C14: 6219 | D14: 51 | E14: 416 | F14: Good | G14: 0 | H14: N | I14: No | L14: Stack 2 | M14: 1 | N14: 3174 | O14: 24.6 | P14: 39.7 | Q14: Good | R14: 7 | S14: N | T14: Yes | AF14: =D14 -> 51 | AG14: =E14 -> 416 | AH14: =G14 -> 0
B15: 2 | C15: 6272 | D15: 92 | E15: 279 | F15: Good | G15: 7.72 | H15: Y | I15: No | M15: 2 | N15: 6230 | O15: 45 | P15: 85.7 | Q15: Good | R15: 7.8 | S15: Y | T15: No | AF15: =D15 -> 92 | AG15: =E15 -> 279 | AH15: =G15 -> 7.72
B16: 3 | C16: 6114 | D16: 80 | E16: 220 | F16: Good | G16: 7.75 | H16: Y | I16: No | M16: 3 | N16: 6234 | O16: 11.3 | P16: 26.7 | Q16: Good | R16: 7.7 | S16: N | T16: Yes | AF16: =D16 -> 80 | AG16: =E16 -> 220 | AH16: =G16 -> 7.75
B17: 4 | C17: 6217 | D17: 41.8 | E17: 181 | F17: Good | G17: 7.8 | H17: N | I17: Yes | M17: 4 | N17: 5000 | O17: 29.9 | P17: 97.7 | Q17: Good | R17: 7.5 | S17: N | T17: Yes | AF17: =D17 -> 41.8 | AG17: =E17 -> 181 | AH17: =G17 -> 7.8
B18: 5 | C18: 6171 | D18: 26.4 | E18: 61.8 | F18: Good | G18: 7.825 | H18: N | I18: Yes | M18: 5 | N18: 6235 | O18: 18 | P18: 32.3 | Q18: Good | R18: 7.8 | S18: N | T18: Yes | AF18: =D18 -> 26.4 | AG18: =E18 -> 61.8 | AH18: =G18 -> 7.825
B19: 6 | C19: 6227 | D19: 11.8 | E19: 28.8 | F19: Good | G19: 7.85 | H19: N | I19: Yes | M19: 6 | N19: 6228 | O19: 21.9 | P19: 46.2 | Q19: Good | R19: 7.8 | S19: N | T19: Yes | AF19: =D19 -> 11.8 | AG19: =E19 -> 28.8 | AH19: =G19 -> 7.85
A20: Stack 3 | B20: 1 | C20: 6285 | D20: 97 | E20: 195 | F20: Good | G20: 7.75 | H20: N | I20: Yes | L20: Stack 3 | M20: 1 | N20: 6000 | O20: 27.2 | P20: 150 | Q20: Good | R20: 7.7 | S20: Y | T20: No | AF20: =D20 -> 97 | AG20: =E20 -> 195 | AH20: =G20 -> 7.75
B21: 2 | C21: 6222 | D21: 42 | E21: 140 | F21: Good | G21: 7.8 | H21: Y | I21: No | M21: 2 | N21: 6461 | O21: 15 | P21: 58.5 | Q21: Good | R21: 7.6 | S21: N | T21: Yes | AF21: =D21 -> 42 | AG21: =E21 -> 140 | AH21: =G21 -> 7.8
B22: 3 | C22: 6284 | D22: 10.5 | E22: 31.7 | F22: Good | G22: 7.75 | H22: N | I22: Yes | M22: 3 | N22: 6001 | O22: 88.7 | P22: 521 | Q22: Good | R22: 7.7 | S22: Y | T22: No | AF22: =D22 -> 10.5 | AG22: =E22 -> 31.7 | AH22: =G22 -> 7.75
B23: 4 | C23: 6287 | D23: 13.2 | E23: 34.5 | F23: Good | G23: 7.68 | H23: N | I23: Yes | M23: 4 | N23: 6002 | O23: 16.1 | P23: 72.6 | Q23: Good | R23: 7.4 | S23: N | T23: Yes | AF23: =D23 -> 13.2 | AG23: =E23 -> 34.5 | AH23: =G23 -> 7.68
B24: 5 | C24: 6286 | D24: 29.2 | E24: 162 | F24: Good | G24: 7.8 | H24: N | I24: Yes | M24: 5 | N24: 3292 | O24: 32 | P24: 79.5 | Q24: Good | R24: 7.8 | S24: N | T24: Yes | AF24: =D24 -> 29.2 | AG24: =E24 -> 162 | AH24: =G24 -> 7.8
B25: 6 | C25: 6220 | D25: 15.7 | E25: 31.5 | F25: Good | G25: 7.8 | H25: N | I25: Yes | M25: 6 | N25: 6003 | O25: 63.4 | P25: 127.8 | Q25: Good | R25: 7.5 | S25: Y | T25: No | AF25: =D25 -> 15.7 | AG25: =E25 -> 31.5 | AH25: =G25 -> 7.8
A26: Stack 4 | B26: 1 | C26: 6260 | D26: 18.4 | E26: 45 | F26: Good | G26: 7.75 | H26: N | I26: Yes | L26: Stack 4 | M26: 1 | N26: 2731 | O26: 18.5 | P26: 62.6 | Q26: Good | R26: 7.2 | S26: N | T26: Yes | AF26: =D26 -> 18.4 | AG26: =E26 -> 45 | AH26: =G26 -> 7.75
B27: 2 | C27: 6264 | D27: 101 | E27: 286 | F27: Good | G27: 7.72 | H27: Y | I27: No | M27: 2 | N27: 3502 | O27: 22.9 | P27: 35.8 | Q27: Good | R27: 7.2 | S27: N | T27: Yes | AF27: =D27 -> 101 | AG27: =E27 -> 286 | AH27: =G27 -> 7.72
B28: 3 | C28: 6263 | D28: 26.9 | E28: 45.2 | F28: Good | G28: 7.7 | H28: N | I28: Yes | M28: 3 | N28: 3356 | O28: 22.5 | P28: 38.8 | Q28: Good | R28: 7.6 | S28: N | T28: Yes | AF28: =D28 -> 26.9 | AG28: =E28 -> 45.2 | AH28: =G28 -> 7.7
B29: 4 | C29: 6262 | D29: 84.7 | E29: 413 | F29: Good | G29: 7.7 | H29: Y | I29: No | M29: 4 | N29: 2874 | O29: 20.4 | P29: 51 | Q29: Good | R29: 7 | S29: N | T29: Yes | AF29: =D29 -> 84.7 | AG29: =E29 -> 413 | AH29: =G29 -> 7.7
B30: 5 | C30: 6294 | D30: 29.3 | E30: 162 | F30: Good | G30: 0 | H30: N | I30: No | M30: 5 | N30: 2969 | O30: 366 | P30: 633.2 | Q30: Good | R30: 7.7 | S30: Y | T30: No | AF30: =D30 -> 29.3 | AG30: =E30 -> 162 | AH30: =G30 -> 0
B31: 6 | C31: 3501 | D31: 15.7 | E31: 31.5 | F31: Good | G31: 0 | H31: N | I31: No | M31: 6 | N31: 2928 | O31: 27.8 | P31: 43.8 | Q31: Good | R31: 7.6 | S31: N | T31: Yes | AF31: =D31 -> 15.7 | AG31: =E31 -> 31.5 | AH31: =G31 -> 0
H32: Num to reuse | I32: =COUNTIF(I6:I31,"Yes") -> 14 | S32: Num to reuse | T32: =COUNTIF(T6:T31,"Yes") -> 15 | AF32: =O8 -> 154.2 | AG32: =P8 -> 495 | AH32: =R8 -> 7.35
AF33: =O9 -> 34.6 | AG33: =P9 -> 71 | AH33: =R9 -> 7.8
A34: Note: Creeping Up = Y means current creeping upwards during measurement. Bad sign device will eventually | L34: Note: Creeping Up = Y means current creeping upwards during measurement. Bad sign device will eventually | AF34: =O10 -> 20.5 | AG34: =P10 -> 43 | AH34: =R10 -> 0
A35: break down under voltage in crowbar tank. | E35: 0 in VBO test means a failure to self-fire | L35: break down under voltage in crowbar tank. | P35: 0 in VBO test means a failure to self-fire | AF35: =O11 -> 81.6 | AG35: =P11 -> 143.5 | AH35: =R11 -> 7.8
AF36: =O12 -> 99.3 | AG36: =P12 -> 276.5 | AH36: =R12 -> 7.4
D37: Conclusions | P37: Conclusions | AF37: =O13 -> 9.3 | AG37: =P13 -> 24.7 | AH37: =R13 -> 7.5
AF38: =O14 -> 24.6 | AG38: =P14 -> 39.7 | AH38: =R14 -> 7
A39: Stacks 2 + 4 were bad. Believe these 2 be the culprit in the second Spear 2 failure (< 2 days run time). | L39: Stack 1 had 3 SCRs with high leakage current and a 4th SCR that failed on over-volts self-fire. | AF39: =O15 -> 45 | AG39: =P15 -> 85.7 | AH39: =R15 -> 7.8
A40: Stack 4 had 4 devices marginal or failed at self-fire (permanent short with one shot). | L40: Stack 3 has 3 SCRs with high leakage current. Both stack 1 + 3 indicate likely strong candidates for | AF40: =O16 -> 11.3 | AG40: =P16 -> 26.7 | AH40: =R16 -> 7.7
L41: Spear 2 failure on July 06, 2018. | AF41: =O17 -> 29.9 | AG41: =P17 -> 97.7 | AH41: =R17 -> 7.5
A42: Stacks 1 + 3 are decent--not great though. Overall, found 10 devices out of 24 either marginal or failed. | AF42: =O18 -> 18 | AG42: =P18 -> 32.3 | AH42: =R18 -> 7.8
L43: Stacks 2 + 4 are reasonably good. | AF43: =O19 -> 21.9 | AG43: =P19 -> 46.2 | AH43: =R19 -> 7.8
...

Sheet Spares Data
A1: Spare SCR tests to rebuild Spear 2 Crowbar Stacks.
D3: 43323
A5: Spare # | B5: Serial # | C5: uA @ 4.2 KV | D5: uA @ 6.5 KV | E5: Fiber Optic | F5: OV Self-Fire | G5: Creeping Up | H5: Good/Bad
A7: 1 | B7: 5654 | C7: 32.7 | D7: 66.4 | E7: Pass | F7: 7.8 | G7: Y | H7: Bad
A8: 2 | B8: 5640 | C8: 11.6 | D8: 40.2 | E8: Pass | F8: 7.75 | G8: N | H8: Good
A9: 3 | B9: 2363 | C9: 23.3 | D9: 37.8 | E9: Pass | F9: 7.1 | G9: N | H9: Good
A10: 4 | B10: 6224 | C10: 13.8 | D10: 30.1 | E10: Pass | F10: 7.795 | G10: N | H10: Good
A11: 5 | B11: 3359 | C11: 10.6 | D11: 17.5 | E11: Pass | F11: 7.05 | G11: N | H11: Good
A12: 6 | B12: 3381 | C12: 15.4 | D12: 42.1 | E12: Pass | F12: 6.95 | G12: Y | H12: Marginal
A13: 7 | B13: 3175 | C13: 9.8 | D13: 16.6 | E13: Pass | F13: 7 | G13: N | H13: Good
A14: 8 | B14: 2998 | C14: 11.4 | D14: 45.6 | E14: Pass | F14: 7.1 | G14: Y | H14: Marginal
A15: 9 | B15: 6279 | C15: 10.7 | D15: 20.5 | E15: Pass | F15: 7.8 | G15: N | H15: Good
A16: 10 | B16: 2360 | C16: 8.7 | D16: 16.2 | E16: Pass | F16: 7 | G16: N | H16: Good
A17: 11 | B17: 3186 | C17: 25.2 | D17: 47.2 | E17: Pass | F17: 7 | G17: N | H17: Good
A18: 12 | B18: 3360 | C18: 4.5 | D18: 9.5 | E18: Pass | F18: 7 | G18: N | H18: Good
... A24: 18 | B24: 6244 | C24: 6.7 | D24: 19.6 | E24: Pass | F24: 7.6 | G24: N | H24: Good
A25: 19
A26: 20
A27: 21
A28: 22
A29: 23
A30: 24
A31: 25
A32: 26
A33: 27
A34: 28
A35: 29
A36: 30
... A40: 34
G41: Num Good | H41: =COUNTIF(H6:H40,"Good") -> 13

Sheet Summary Data for Graphics
C3: Serial # | D3: uA @ 4.2 KV | E3: uA @ 6.5KV | F3: F.O. Trigs | G3: OV Self-Fire | H3: Creeping Up | I3: Re-Use? | K3: # good dev | L3: # bad dev | M3: # marginal
A4: Set 2 | B4: Stack 1 | C4: ='Operational Data'!C8 -> 2436 | D4: ='Operational Data'!D8 -> 10.1 | E4: ='Operational Data'!E8 -> 17.7 | F4: ='Operational Data'!F8 -> Good | G4: ='Operational Data'!G8 -> 7.7 | H4: ='Operational Data'!H8 -> N | I4: ='Operational Data'!I8 -> Yes | K4: =COUNTIF(I4:I69, "Yes") + COUNTIF(I4:I69,"Good") -> 42 | L4: =COUNTIF(I4:I69, "No") + COUNTIF(I4:I69,"Bad") -> 20 | M4: =COUNTIF(I4:I69, "Marginal") -> 4
C5: ='Operational Data'!C9 -> 2364 | D5: ='Operational Data'!D9 -> 28.8 | E5: ='Operational Data'!E9 -> 49.2 | F5: ='Operational Data'!F9 -> Good | G5: ='Operational Data'!G9 -> 7.3 | H5: ='Operational Data'!H9 -> N | I5: ='Operational Data'!I9 -> Yes
C6: ='Operational Data'!C10 -> 2362 | D6: ='Operational Data'!D10 -> 23.4 | E6: ='Operational Data'!E10 -> 64.2 | F6: ='Operational Data'!F10 -> Good | G6: ='Operational Data'!G10 -> 0 | H6: ='Operational Data'!H10 -> N | I6: ='Operational Data'!I10 -> No
C7: ='Operational Data'!C11 -> 2357 | D7: ='Operational Data'!D11 -> 25.5 | E7: ='Operational Data'!E11 -> 42.4 | F7: ='Operational Data'!F11 -> Good | G7: ='Operational Data'!G11 -> 7.3 | H7: ='Operational Data'!H11 -> N | I7: ='Operational Data'!I11 -> Yes
C8: ='Operational Data'!C12 -> 2361 | D8: ='Operational Data'!D12 -> 11.6 | E8: ='Operational Data'!E12 -> 21.5 | F8: ='Operational Data'!F12 -> Good | G8: ='Operational Data'!G12 -> 7.2 | H8: ='Operational Data'!H12 -> N | I8: ='Operational Data'!I12 -> Yes
C9: ='Operational Data'!C13 -> 5636 | D9: ='Operational Data'!D13 -> 57.4 | E9: ='Operational Data'!E13 -> 94.2 | F9: ='Operational Data'!F13 -> Good | G9: ='Operational Data'!G13 -> 7.5 | H9: ='Operational Data'!H13 -> Y | I9: ='Operational Data'!I13 -> No
B10: Stack 2 | C10: ='Operational Data'!C14 -> 6219 | D10: ='Operational Data'!D14 -> 51 | E10: ='Operational Data'!E14 -> 416 | F10: ='Operational Data'!F14 -> Good | G10: ='Operational Data'!G14 -> 0 | H10: ='Operational Data'!H14 -> N | I10: ='Operational Data'!I14 -> No
C11: ='Operational Data'!C15 -> 6272 | D11: ='Operational Data'!D15 -> 92 | E11: ='Operational Data'!E15 -> 279 | F11: ='Operational Data'!F15 -> Good | G11: ='Operational Data'!G15 -> 7.72 | H11: ='Operational Data'!H15 -> Y | I11: ='Operational Data'!I15 -> No
C12: ='Operational Data'!C16 -> 6114 | D12: ='Operational Data'!D16 -> 80 | E12: ='Operational Data'!E16 -> 220 | F12: ='Operational Data'!F16 -> Good | G12: ='Operational Data'!G16 -> 7.75 | H12: ='Operational Data'!H16 -> Y | I12: ='Operational Data'!I16 -> No
C13: ='Operational Data'!C17 -> 6217 | D13: ='Operational Data'!D17 -> 41.8 | E13: ='Operational Data'!E17 -> 181 | F13: ='Operational Data'!F17 -> Good | G13: ='Operational Data'!G17 -> 7.8 | H13: ='Operational Data'!H17 -> N | I13: ='Operational Data'!I17 -> Yes
C14: ='Operational Data'!C18 -> 6171 | D14: ='Operational Data'!D18 -> 26.4 | E14: ='Operational Data'!E18 -> 61.8 | F14: ='Operational Data'!F18 -> Good | G14: ='Operational Data'!G18 -> 7.825 | H14: ='Operational Data'!H18 -> N | I14: ='Operational Data'!I18 -> Yes
C15: ='Operational Data'!C19 -> 6227 | D15: ='Operational Data'!D19 -> 11.8 | E15: ='Operational Data'!E19 -> 28.8 | F15: ='Operational Data'!F19 -> Good | G15: ='Operational Data'!G19 -> 7.85 | H15: ='Operational Data'!H19 -> N | I15: ='Operational Data'!I19 -> Yes
B16: Stack 3 | C16: ='Operational Data'!C20 -> 6285 | D16: ='Operational Data'!D20 -> 97 | E16: ='Operational Data'!E20 -> 195 | F16: ='Operational Data'!F20 -> Good | G16: ='Operational Data'!G20 -> 7.75 | H16: ='Operational Data'!H20 -> N | I16: ='Operational Data'!I20 -> Yes
C17: ='Operational Data'!C21 -> 6222 | D17: ='Operational Data'!D21 -> 42 | E17: ='Operational Data'!E21 -> 140 | F17: ='Operational Data'!F21 -> Good | G17: ='Operational Data'!G21 -> 7.8 | H17: ='Operational Data'!H21 -> Y | I17: ='Operational Data'!I21 -> No
C18: ='Operational Data'!C22 -> 6284 | D18: ='Operational Data'!D22 -> 10.5 | E18: ='Operational Data'!E22 -> 31.7 | F18: ='Operational Data'!F22 -> Good | G18: ='Operational Data'!G22 -> 7.75 | H18: ='Operational Data'!H22 -> N | I18: ='Operational Data'!I22 -> Yes
C19: ='Operational Data'!C23 -> 6287 | D19: ='Operational Data'!D23 -> 13.2 | E19: ='Operational Data'!E23 -> 34.5 | F19: ='Operational Data'!F23 -> Good | G19: ='Operational Data'!G23 -> 7.68 | H19: ='Operational Data'!H23 -> N | I19: ='Operational Data'!I23 -> Yes
C20: ='Operational Data'!C24 -> 6286 | D20: ='Operational Data'!D24 -> 29.2 | E20: ='Operational Data'!E24 -> 162 | F20: ='Operational Data'!F24 -> Good | G20: ='Operational Data'!G24 -> 7.8 | H20: ='Operational Data'!H24 -> N | I20: ='Operational Data'!I24 -> Yes
C21: ='Operational Data'!C25 -> 6220 | D21: ='Operational Data'!D25 -> 15.7 | E21: ='Operational Data'!E25 -> 31.5 | F21: ='Operational Data'!F25 -> Good | G21: ='Operational Data'!G25 -> 7.8 | H21: ='Operational Data'!H25 -> N | I21: ='Operational Data'!I25 -> Yes
B22: Stack 4 | C22: ='Operational Data'!C26 -> 6260 | D22: ='Operational Data'!D26 -> 18.4 | E22: ='Operational Data'!E26 -> 45 | F22: ='Operational Data'!F26 -> Good | G22: ='Operational Data'!G26 -> 7.75 | H22: ='Operational Data'!H26 -> N | I22: ='Operational Data'!I26 -> Yes
C23: ='Operational Data'!C27 -> 6264 | D23: ='Operational Data'!D27 -> 101 | E23: ='Operational Data'!E27 -> 286 | F23: ='Operational Data'!F27 -> Good | G23: ='Operational Data'!G27 -> 7.72 | H23: ='Operational Data'!H27 -> Y | I23: ='Operational Data'!I27 -> No
C24: ='Operational Data'!C28 -> 6263 | D24: ='Operational Data'!D28 -> 26.9 | E24: ='Operational Data'!E28 -> 45.2 | F24: ='Operational Data'!F28 -> Good | G24: ='Operational Data'!G28 -> 7.7 | H24: ='Operational Data'!H28 -> N | I24: ='Operational Data'!I28 -> Yes
C25: ='Operational Data'!C29 -> 6262 | D25: ='Operational Data'!D29 -> 84.7 | E25: ='Operational Data'!E29 -> 413 | F25: ='Operational Data'!F29 -> Good | G25: ='Operational Data'!G29 -> 7.7 | H25: ='Operational Data'!H29 -> Y | I25: ='Operational Data'!I29 -> No
C26: ='Operational Data'!C30 -> 6294 | D26: ='Operational Data'!D30 -> 29.3 | E26: ='Operational Data'!E30 -> 162 | F26: ='Operational Data'!F30 -> Good | G26: ='Operational Data'!G30 -> 0 | H26: ='Operational Data'!H30 -> N | I26: ='Operational Data'!I30 -> No
C27: ='Operational Data'!C31 -> 3501 | D27: ='Operational Data'!D31 -> 15.7 | E27: ='Operational Data'!E31 -> 31.5 | F27: ='Operational Data'!F31 -> Good | G27: ='Operational Data'!G31 -> 0 | H27: ='Operational Data'!H31 -> N | I27: ='Operational Data'!I31 -> No
A28: Set 1 | B28: Stack 1 | C28: ='Operational Data'!N8 -> 2326 | D28: ='Operational Data'!O8 -> 154.2 | E28: ='Operational Data'!P8 -> 495 | F28: ='Operational Data'!Q8 -> Good | G28: ='Operational Data'!R8 -> 7.35 | H28: ='Operational Data'!S8 -> Y | I28: ='Operational Data'!T8 -> No
C29: ='Operational Data'!N9 -> 2322 | D29: ='Operational Data'!O9 -> 34.6 | E29: ='Operational Data'!P9 -> 71 | F29: ='Operational Data'!Q9 -> Good | G29: ='Operational Data'!R9 -> 7.8 | H29: ='Operational Data'!S9 -> N | I29: ='Operational Data'!T9 -> Yes
C30: ='Operational Data'!N10 -> 2319 | D30: ='Operational Data'!O10 -> 20.5 | E30: ='Operational Data'!P10 -> 43 | F30: ='Operational Data'!Q10 -> Good | G30: ='Operational Data'!R10 -> 0 | H30: ='Operational Data'!S10 -> N | I30: ='Operational Data'!T10 -> No
C31: ='Operational Data'!N11 -> 2428 | D31: ='Operational Data'!O11 -> 81.6 | E31: ='Operational Data'!P11 -> 143.5 | F31: ='Operational Data'!Q11 -> Good | G31: ='Operational Data'!R11 -> 7.8 | H31: ='Operational Data'!S11 -> Y | I31: ='Operational Data'!T11 -> No
C32: ='Operational Data'!N12 -> 2429 | D32: ='Operational Data'!O12 -> 99.3 | E32: ='Operational Data'!P12 -> 276.5 | F32: ='Operational Data'!Q12 -> Good | G32: ='Operational Data'!R12 -> 7.4 | H32: ='Operational Data'!S12 -> Y | I32: ='Operational Data'!T12 -> No
C33: ='Operational Data'!N13 -> 2350 | D33: ='Operational Data'!O13 -> 9.3 | E33: ='Operational Data'!P13 -> 24.7 | F33: ='Operational Data'!Q13 -> Good | G33: ='Operational Data'!R13 -> 7.5 | H33: ='Operational Data'!S13 -> N | I33: ='Operational Data'!T13 -> Yes
B34: Stack 2 | C34: ='Operational Data'!N14 -> 3174 | D34: ='Operational Data'!O14 -> 24.6 | E34: ='Operational Data'!P14 -> 39.7 | F34: ='Operational Data'!Q14 -> Good | G34: ='Operational Data'!R14 -> 7 | H34: ='Operational Data'!S14 -> N | I34: ='Operational Data'!T14 -> Yes
C35: ='Operational Data'!N15 -> 6230 | D35: ='Operational Data'!O15 -> 45 | E35: ='Operational Data'!P15 -> 85.7 | F35: ='Operational Data'!Q15 -> Good | G35: ='Operational Data'!R15 -> 7.8 | H35: ='Operational Data'!S15 -> Y | I35: ='Operational Data'!T15 -> No
C36: ='Operational Data'!N16 -> 6234 | D36: ='Operational Data'!O16 -> 11.3 | E36: ='Operational Data'!P16 -> 26.7 | F36: ='Operational Data'!Q16 -> Good | G36: ='Operational Data'!R16 -> 7.7 | H36: ='Operational Data'!S16 -> N | I36: ='Operational Data'!T16 -> Yes
C37: ='Operational Data'!N17 -> 5000 | D37: ='Operational Data'!O17 -> 29.9 | E37: ='Operational Data'!P17 -> 97.7 | F37: ='Operational Data'!Q17 -> Good | G37: ='Operational Data'!R17 -> 7.5 | H37: ='Operational Data'!S17 -> N | I37: ='Operational Data'!T17 -> Yes
C38: ='Operational Data'!N18 -> 6235 | D38: ='Operational Data'!O18 -> 18 | E38: ='Operational Data'!P18 -> 32.3 | F38: ='Operational Data'!Q18 -> Good | G38: ='Operational Data'!R18 -> 7.8 | H38: ='Operational Data'!S18 -> N | I38: ='Operational Data'!T18 -> Yes
C39: ='Operational Data'!N19 -> 6228 | D39: ='Operational Data'!O19 -> 21.9 | E39: ='Operational Data'!P19 -> 46.2 | F39: ='Operational Data'!Q19 -> Good | G39: ='Operational Data'!R19 -> 7.8 | H39: ='Operational Data'!S19 -> N | I39: ='Operational Data'!T19 -> Yes
B40: Stack 3 | C40: ='Operational Data'!N20 -> 6000 | D40: ='Operational Data'!O20 -> 27.2 | E40: ='Operational Data'!P20 -> 150 | F40: ='Operational Data'!Q20 -> Good | G40: ='Operational Data'!R20 -> 7.7 | H40: ='Operational Data'!S20 -> Y | I40: ='Operational Data'!T20 -> No
C41: ='Operational Data'!N21 -> 6461 | D41: ='Operational Data'!O21 -> 15 | E41: ='Operational Data'!P21 -> 58.5 | F41: ='Operational Data'!Q21 -> Good | G41: ='Operational Data'!R21 -> 7.6 | H41: ='Operational Data'!S21 -> N | I41: ='Operational Data'!T21 -> Yes
C42: ='Operational Data'!N22 -> 6001 | D42: ='Operational Data'!O22 -> 88.7 | E42: ='Operational Data'!P22 -> 521 | F42: ='Operational Data'!Q22 -> Good | G42: ='Operational Data'!R22 -> 7.7 | H42: ='Operational Data'!S22 -> Y | I42: ='Operational Data'!T22 -> No
...

Sheet Replacement Stacks 1
A2: New Set of Crowbar Stacks for Spear 2 RF HVPS 18 Aug 2018
A4: Stack 1 | B4: SCR S/N | C4: Stack Leakage @ 25 KVDC | D4: Fiber Optic Trig Test | E4: Pass/Fail | G4: Old #
A5: Cell 1 | B5: 6239
A6: Cell 2 | B6: 3359
A7: Cell 3 | B7: 6461 | C7: 0.846 uA | D7: Pass | E7: Pass | G7: 0.85
A8: Cell 4 | B8: 6279
A9: Cell 5 | B9: 3175
A10: Cell 6 | B10: 2350
A12: Stack 2
A13: Cell 1 | B13: 2360
A14: Cell 2 | B14: 2322
A15: Cell 3 | B15: 3502 | C15: .859 uA | D15: Pass | E15: Pass
A16: Cell 4 | B16: 2731
A17: Cell 5 | B17: 3186
A18: Cell 6 | B18: 5653
A20: Stack 3
A21: Cell 1 | B21: 6239
A22: Cell 2 | B22: 2361
A23: Cell 3 | B23: 2874 | C23: .848 uA | D23: Pass | E23: Pass | G23: 0.868
A24: Cell 4 | B24: 3292
A25: Cell 5 | B25: 2436
A26: Cell 6 | B26: 6244
A28: Stack 4
A29: Cell 1 | B29: 6234
A30: Cell 2 | B30: 3356
A31: Cell 3 | B31: 5000 | C31: .851 uA | D31: Pass | E31: Pass
A32: Cell 4 | B32: 6220
A33: Cell 5 | B33: 6284
A34: Cell 6 | B34: 3360

Sheet Replacement Stacks 2
A1: Ohm Tests for New Spear 2 Crowbar Stacks | I1: 43333 | O1: Ohm Tests for New Spear 2 Crowbar Stacks | W1: 43333
I2: Updated | W2: Updated
A3: Fwd Direction | C3: Ohms (Meas) | D3: Volts | E3: Current | F3: Ohms (Calc) | G3: LTT Current | H3: LTT Ohms (Calc) | I3: 43334 | O3: Reverse Direction | Q3: Ohms (Meas) | R3: Volts | S3: Current | T3: Ohms (Calc) | U3: LTT Current | V3: LTT Ohms (Calc) | W3: 43334
C4: M Ohms | E4: mA | F4: M Ohms | G4: uA | H4: M Ohms | Q4: M Ohms | S4: mA | T4: M Ohms | U4: uA | V4: M Ohms
K5: Old #s | Y5: Old #s
A6: Stack 1 | B6: Replace S/N | C6: 29.3 | D6: 10488 | E6: 0.355 | F6: =D6/E6*0.001 -> 29.543662 | J6: 27.3 | K6: 10489 | L6: 0.394 | M6: =K6/L6*0.001 -> 26.621827 | O6: Stack 1 | P6: Replace S/N | Q6: 29.5 | R6: 10488 | S6: 0.356 | T6: =R6/S6*0.001 -> 29.460674 | X6: 27.4 | Y6: 10489 | Z6: 0.383 | AA6: =Y6/Z6*0.001 -> 27.386423
A7: 1 | C7: 4.78 | D7: 5233 | E7: 1.09 | F7: =D7/E7*0.001 -> 4.8009174 | G7: =(E7-D7/5000)*1000 -> 43.4 | H7: =D7/(E7*0.001 - D7/5000000)*0.000001 -> 120.57604 | O7: 1 | Q7: 4.79 | R7: 5232 | S7: 1.09 | T7: =R7/S7*0.001 -> 4.8 | U7: =(S7-R7/5000)*1000 -> 43.6 | V7: =R7/(S7*0.001 - R7/5000000)*0.000001 -> 120
A8: 2 | B8: 3359 | C8: 4.98 | D8: 5234 | E8: 1.05 | F8: =D8/E8*0.001 -> 4.9847619 | G8: =(E8-D8/5000)*1000 -> 3.2 | H8: =D8/(E8*0.001 - D8/5000000)*0.000001 -> 1635.625 | J8: 4.7 | K8: 5232 | L8: 1.11 | M8: =K8/L8*0.001 -> 4.7135135 | O8: 2 | P8: 3359 | Q8: 4.99 | R8: 5235 | S8: 1.05 | T8: =R8/S8*0.001 -> 4.9857143 | U8: =(S8-R8/5000)*1000 -> 3 | V8: =R8/(S8*0.001 - R8/5000000)*0.000001 -> 1745 | X8: 4.5 | Y8: 5231 | Z8: 1.16 | AA8: =Y8/Z8*0.001 -> 4.5094828
A9: 3 | C9: 4.76 | D9: 5232 | E9: 1.1 | F9: =D9/E9*0.001 -> 4.7563636 | G9: =(E9-D9/5000)*1000 -> 53.6 | H9: =D9/(E9*0.001 - D9/5000000)*0.000001 -> 97.61194 | O9: 3 | Q9: 4.67 | R9: 5231 | S9: 1.12 | T9: =R9/S9*0.001 -> 4.6705357 | U9: =(S9-R9/5000)*1000 -> 73.8 | V9: =R9/(S9*0.001 - R9/5000000)*0.000001 -> 70.880759
A10: 4 | B10: 6279 | C10: 4.96 | D10: 5233 | E10: 1.06 | F10: =D10/E10*0.001 -> 4.9367925 | G10: =(E10-D10/5000)*1000 -> 13.4 | H10: =D10/(E10*0.001 - D10/5000000)*0.000001 -> 390.52239 | J10: 4.7 | K10: 5232 | L10: 1.11 | M10: =K10/L10*0.001 -> 4.7135135 | O10: 4 | P10: 6279 | Q10: 4.92 | R10: 5235 | S10: 1.07 | T10: =R10/S10*0.001 -> 4.8925234 | U10: =(S10-R10/5000)*1000 -> 23 | V10: =R10/(S10*0.001 - R10/5000000)*0.000001 -> 227.6087 | X10: 4.81 | Y10: 5232 | Z10: 1.09 | AA10: =Y10/Z10*0.001 -> 4.8
A11: 5 | B11: 3175 | C11: 4.92 | D11: 5233 | E11: 1.06 | F11: =D11/E11*0.001 -> 4.9367925 | G11: =(E11-D11/5000)*1000 -> 13.4 | H11: =D11/(E11*0.001 - D11/5000000)*0.000001 -> 390.52239 | J11: 4.55 | K11: 5231 | L11: 1.15 | M11: =K11/L11*0.001 -> 4.5486957 | O11: 5 | P11: 3175 | Q11: 4.92 | R11: 5234 | S11: 1.06 | T11: =R11/S11*0.001 -> 4.9377358 | U11: =(S11-R11/5000)*1000 -> 13.2 | V11: =R11/(S11*0.001 - R11/5000000)*0.000001 -> 396.51515 | X11: 4.19 | Y11: 5230 | Z11: 1.25 | AA11: =Y11/Z11*0.001 -> 4.184
A12: 6 | C12: 4.9 | D12: 5232 | E12: 1.07 | F12: =D12/E12*0.001 -> 4.8897196 | G12: =(E12-D12/5000)*1000 -> 23.6 | H12: =D12/(E12*0.001 - D12/5000000)*0.000001 -> 221.69492 | J12: Replaced SCRs 2,4, 5 in stack 1. | O12: 6 | Q12: 4.87 | R12: 5233 | S12: 1.09 | T12: =R12/S12*0.001 -> 4.8009174 | U12: =(S12-R12/5000)*1000 -> 43.4 | V12: =R12/(S12*0.001 - R12/5000000)*0.000001 -> 120.57604 | X12: Replaced SCRs 2,4, 5 in stack 1.
B13: Total | C13: =SUM(C7:C12) -> 29.3 | D13: AVG: | E13: =AVERAGE(E7:E12) -> 1.0716667 | F13: =SUM(F7:F12) -> 29.305348 | J13: Test results updated. | P13: Total | Q13: =SUM(Q7:Q12) -> 29.16 | R13: AVG: | S13: =AVERAGE(S7:S12) -> 1.08 | T13: =SUM(T7:T12) -> 29.087427 | X13: Test results updated.
A15: Stack 2 | C15: 29.3 | D15: 10491 | E15: 0.358 | F15: =D15/E15*0.001 -> 29.304469 | O15: Stack 2 | Q15: 29.3 | R15: 10490 | S15: 0.358 | T15: =R15/S15*0.001 -> 29.301676
A16: 1 | C16: 4.94 | D16: 5234 | E16: 1.06 | F16: =D16/E16*0.001 -> 4.9377358 | G16: =(E16-D16/5000)*1000 -> 13.2 | H16: =D16/(E16*0.001 - D16/5000000)*0.000001 -> 396.51515 | O16: 1 | Q16: 4.95 | R16: 5234 | S16: 1.06 | T16: =R16/S16*0.001 -> 4.9377358 | U16: =(S16-R16/5000)*1000 -> 13.2 | V16: =R16/(S16*0.001 - R16/5000000)*0.000001 -> 396.51515
A17: 2 | C17: 4.75 | D17: 5233 | E17: 1.1 | F17: =D17/E17*0.001 -> 4.7572727 | G17: =(E17-D17/5000)*1000 -> 53.4 | H17: =D17/(E17*0.001 - D17/5000000)*0.000001 -> 97.996255 | O17: 2 | Q17: 4.84 | R17: 5233 | S17: 1.08 | T17: =R17/S17*0.001 -> 4.8453704 | U17: =(S17-R17/5000)*1000 -> 33.4 | V17: =R17/(S17*0.001 - R17/5000000)*0.000001 -> 156.67665
A18: 3 | C18: 4.9 | D18: 5235 | E18: 1.07 | F18: =D18/E18*0.001 -> 4.8925234 | G18: =(E18-D18/5000)*1000 -> 23 | H18: =D18/(E18*0.001 - D18/5000000)*0.000001 -> 227.6087 | O18: 3 | Q18: 4.91 | R18: 5234 | S18: 1.07 | T18: =R18/S18*0.001 -> 4.8915888 | U18: =(S18-R18/5000)*1000 -> 23.2 | V18: =R18/(S18*0.001 - R18/5000000)*0.000001 -> 225.60345
A19: 4 | C19: 4.89 | D19: 5235 | E19: 1.07 | F19: =D19/E19*0.001 -> 4.8925234 | G19: =(E19-D19/5000)*1000 -> 23 | H19: =D19/(E19*0.001 - D19/5000000)*0.000001 -> 227.6087 | O19: 4 | Q19: 4.89 | R19: 5234 | S19: 1.07 | T19: =R19/S19*0.001 -> 4.8915888 | U19: =(S19-R19/5000)*1000 -> 23.2 | V19: =R19/(S19*0.001 - R19/5000000)*0.000001 -> 225.60345
A20: 5 | C20: 4.85 | D20: 5233 | E20: 1.08 | F20: =D20/E20*0.001 -> 4.8453704 | G20: =(E20-D20/5000)*1000 -> 33.4 | H20: =D20/(E20*0.001 - D20/5000000)*0.000001 -> 156.67665 | O20: 5 | Q20: 4.85 | R20: 5233 | S20: 1.08 | T20: =R20/S20*0.001 -> 4.8453704 | U20: =(S20-R20/5000)*1000 -> 33.4 | V20: =R20/(S20*0.001 - R20/5000000)*0.000001 -> 156.67665
A21: 6 | C21: 4.97 | D21: 5235 | E21: 1.05 | F21: =D21/E21*0.001 -> 4.9857143 | G21: =(E21-D21/5000)*1000 -> 3 | H21: =D21/(E21*0.001 - D21/5000000)*0.000001 -> 1745 | O21: 6 | Q21: 4.96 | R21: 5234 | S21: 1.06 | T21: =R21/S21*0.001 -> 4.9377358 | U21: =(S21-R21/5000)*1000 -> 13.2 | V21: =R21/(S21*0.001 - R21/5000000)*0.000001 -> 396.51515
B22: Total | C22: =SUM(C16:C21) -> 29.3 | D22: AVG: | E22: =AVERAGE(E16:E21) -> 1.0716667 | F22: =SUM(F16:F21) -> 29.31114 | P22: Total | Q22: =SUM(Q16:Q21) -> 29.4 | R22: AVG: | S22: =AVERAGE(S16:S21) -> 1.07 | T22: =SUM(T16:T21) -> 29.34939
K23: Old #'s | Y23: Old #'s
A24: Stack 3 | C24: 29.5 | D24: 10495 | E24: 0.356 | F24: =D24/E24*0.001 -> 29.480337 | J24: 28.1 | K24: 10489 | L24: 0.374 | M24: =K24/L24*0.001 -> 28.045455 | O24: Stack 3 | Q24: 29.4 | R24: 10494 | S24: 0.357 | T24: =R24/S24*0.001 -> 29.394958 | X24: 27.9 | Y24: 10491 | Z24: 0.376 | AA24: =Y24/Z24*0.001 -> 27.901596
A25: 1 | C25: 4.96 | D25: 5235 | E25: 1.06 | F25: =D25/E25*0.001 -> 4.9386792 | G25: =(E25-D25/5000)*1000 -> 13 | H25: =D25/(E25*0.001 - D25/5000000)*0.000001 -> 402.69231 | O25: 1 | Q25: 4.89 | R25: 5234 | S25: 1.07 | T25: =R25/S25*0.001 -> 4.8915888 | U25: =(S25-R25/5000)*1000 -> 23.2 | V25: =R25/(S25*0.001 - R25/5000000)*0.000001 -> 225.60345
A26: 2 | B26: 2361 | C26: 4.97 | D26: 5235 | E26: 1.05 | F26: =D26/E26*0.001 -> 4.9857143 | G26: =(E26-D26/5000)*1000 -> 3 | H26: =D26/(E26*0.001 - D26/5000000)*0.000001 -> 1745 | J26: 4.5 | K26: 5232 | L26: 1.16 | M26: =K26/L26*0.001 -> 4.5103448 | O26: 2 | Q26: 4.67 | R26: 5233 | S26: 1.12 | T26: =R26/S26*0.001 -> 4.6723214 | U26: =(S26-R26/5000)*1000 -> 73.4 | V26: =R26/(S26*0.001 - R26/5000000)*0.000001 -> 71.294278 | X26: 4.67 | Y26: 5233 | Z26: 1.12 | AA26: =Y26/Z26*0.001 -> 4.6723214
A27: 3 | C27: 4.78 | D27: 5233 | E27: 1.1 | F27: =D27/E27*0.001 -> 4.7572727 | G27: =(E27-D27/5000)*1000 -> 53.4 | H27: =D27/(E27*0.001 - D27/5000000)*0.000001 -> 97.996255 | O27: 3 | Q27: 4.96 | R27: 5235 | S27: 1.06 | T27: =R27/S27*0.001 -> 4.9386792 | U27: =(S27-R27/5000)*1000 -> 13 | V27: =R27/(S27*0.001 - R27/5000000)*0.000001 -> 402.69231
A28: 4 | C28: 4.84 | D28: 5233 | E28: 1.08 | F28: =D28/E28*0.001 -> 4.8453704 | G28: =(E28-D28/5000)*1000 -> 33.4 | H28: =D28/(E28*0.001 - D28/5000000)*0.000001 -> 156.67665 | O28: 4 | Q28: 4.65 | R28: 5232 | S28: 1.13 | T28: =R28/S28*0.001 -> 4.6300885 | U28: =(S28-R28/5000)*1000 -> 83.6 | V28: =R28/(S28*0.001 - R28/5000000)*0.000001 -> 62.583732
A29: 5 | B29: 2436 | C29: 4.97 | D29: 5235 | E29: 1.05 | F29: =D29/E29*0.001 -> 4.9857143 | G29: =(E29-D29/5000)*1000 -> 3 | H29: =D29/(E29*0.001 - D29/5000000)*0.000001 -> 1745 | J29: 4.65 | K29: 5232 | L29: 1.12 | M29: =K29/L29*0.001 -> 4.6714286 | O29: 5 | Q29: 4.8 | R29: 5233 | S29: 1.05 | T29: =R29/S29*0.001 -> 4.9838095 | U29: =(S29-R29/5000)*1000 -> 3.4 | V29: =R29/(S29*0.001 - R29/5000000)*0.000001 -> 1539.1176 | X29: 4.8 | Y29: 5233 | Z29: 1.09 | AA29: =Y29/Z29*0.001 -> 4.8009174
A30: 6 | C30: 4.94 | D30: 5234 | E30: 1.06 | F30: =D30/E30*0.001 -> 4.9377358 | G30: =(E30-D30/5000)*1000 -> 13.2 | H30: =D30/(E30*0.001 - D30/5000000)*0.000001 -> 396.51515 | J30: Replaced SCRs 2 + 5. Test results | O30: 6 | Q30: 4.87 | R30: 5233 | S30: 1.07 | T30: =R30/S30*0.001 -> 4.8906542 | U30: =(S30-R30/5000)*1000 -> 23.4 | V30: =R30/(S30*0.001 - R30/5000000)*0.000001 -> 223.63248 | X30: Replaced SCRs 2 + 5. Test results
B31: Total | C31: =SUM(C25:C30) -> 29.46 | D31: AVG: | E31: =AVERAGE(E25:E30) -> 1.0666667 | F31: =SUM(F25:F30) -> 29.450487 | J31: updated. | P31: Total | Q31: =SUM(Q25:Q30) -> 28.84 | R31: AVG: | S31: =AVERAGE(S25:S30) -> 1.0833333 | T31: =SUM(T25:T30) -> 29.007142 | X31: updated.
A33: Stack 4 | C33: 29.5 | D33: 10493 | E33: 0.355 | F33: =D33/E33*0.001 -> 29.557746 | O33: Stack 4 | Q33: 27.7 | R33: 10489 | S33: 0.378 | T33: =R33/S33*0.001 -> 27.748677
A34: 1 | C34: 4.92 | D34: 5235 | E34: 1.06 | F34: =D34/E34*0.001 -> 4.9386792 | G34: =(E34-D34/5000)*1000 -> 13 | H34: =D34/(E34*0.001 - D34/5000000)*0.000001 -> 402.69231 | O34: 1 | Q34: 4.88 | R34: 5234 | S34: 1.07 | T34: =R34/S34*0.001 -> 4.8915888 | U34: =(S34-R34/5000)*1000 -> 23.2 | V34: =R34/(S34*0.001 - R34/5000000)*0.000001 -> 225.60345
A35: 2 | C35: 4.92 | D35: 5235 | E35: 1.06 | F35: =D35/E35*0.001 -> 4.9386792 | G35: =(E35-D35/5000)*1000 -> 13 | H35: =D35/(E35*0.001 - D35/5000000)*0.000001 -> 402.69231 | O35: 2 | Q35: 4.92 | R35: 5235 | S35: 1.06 | T35: =R35/S35*0.001 -> 4.9386792 | U35: =(S35-R35/5000)*1000 -> 13 | V35: =R35/(S35*0.001 - R35/5000000)*0.000001 -> 402.69231
A36: 3 | C36: 4.83 | D36: 5234 | E36: 1.08 | F36: =D36/E36*0.001 -> 4.8462963 | G36: =(E36-D36/5000)*1000 -> 33.2 | H36: =D36/(E36*0.001 - D36/5000000)*0.000001 -> 157.6506 | O36: 3 | Q36: 4.75 | R36: 5233 | S36: 1.1 | T36: =R36/S36*0.001 -> 4.7572727 | U36: =(S36-R36/5000)*1000 -> 53.4 | V36: =R36/(S36*0.001 - R36/5000000)*0.000001 -> 97.996255
A37: 4 | C37: 4.91 | D37: 5235 | E37: 1.07 | F37: =D37/E37*0.001 -> 4.8925234 | G37: =(E37-D37/5000)*1000 -> 23 | H37: =D37/(E37*0.001 - D37/5000000)*0.000001 -> 227.6087 | O37: 4 | Q37: 4.82 | R37: 5234 | S37: 1.08 | T37: =R37/S37*0.001 -> 4.8462963 | U37: =(S37-R37/5000)*1000 -> 33.2 | V37: =R37/(S37*0.001 - R37/5000000)*0.000001 -> 157.6506
A38: 5 | C38: 4.95 | D38: 5236 | E38: 1.06 | F38: =D38/E38*0.001 -> 4.9396226 | G38: =(E38-D38/5000)*1000 -> 12.8 | H38: =D38/(E38*0.001 - D38/5000000)*0.000001 -> 409.0625 | O38: 5 | Q38: 4.71 | R38: 5233 | S38: 1.11 | T38: =R38/S38*0.001 -> 4.7144144 | U38: =(S38-R38/5000)*1000 -> 63.4 | V38: =R38/(S38*0.001 - R38/5000000)*0.000001 -> 82.539432
A39: 6 | C39: 4.98 | D39: 5236 | E39: 1.05 | F39: =D39/E39*0.001 -> 4.9866667 | G39: =(E39-D39/5000)*1000 -> 2.8 | H39: =D39/(E39*0.001 - D39/5000000)*0.000001 -> 1870 | O39: 6 | Q39: 4.98 | R39: 5235 | S39: 1.05 | T39: =R39/S39*0.001 -> 4.9857143 | U39: =(S39-R39/5000)*1000 -> 3 | V39: =R39/(S39*0.001 - R39/5000000)*0.000001 -> 1745
B40: Total | C40: =SUM(C34:C39) -> 29.51 | D40: AVG: | E40: =AVERAGE(E34:E39) -> 1.0633333 | F40: =SUM(F34:F39) -> 29.542467 | P40: Total | Q40: =SUM(Q34:Q39) -> 29.06 | R40: AVG: | S40: =AVERAGE(S34:S39) -> 1.0783333 | T40: =SUM(T34:T39) -> 29.133966

Sheet Temperature Dependence
A1: Preliminary Temperature Dependence Tests
A3: S/N | B3: Temp degC | C3: uA @ 4.2 KV | D3: uA @ 6.5KV
A4: 6235 | B4: 32.9 | C4: 32.5 | D4: 50.9
B5: 49 | C5: 41.7 | D5: 68.3
B6: 54 | C6: 44.1 | D6: 72.7

Sheet infineon devices for test
A1: 43343
D2: SCRs sent to Infineon for analysis
A4: Number | B4: S/N | C4: Date Code | E4: copy of results from testing | M4: Set | N4: Stack | P4: Infineon report
A6: 1 | B6: 2969 | C6: 26R9 | E6: ='Summary Data for Graphics'!C50 -> 2969 | F6: ='Summary Data for Graphics'!D50 -> 366 | G6: ='Summary Data for Graphics'!E50 -> 633.2 | H6: ='Summary Data for Graphics'!F50 -> Good | I6: ='Summary Data for Graphics'!G50 -> 7.7 | J6: ='Summary Data for Graphics'!H50 -> Y | K6: ='Summary Data for Graphics'!I50 -> No | M6: 1 | N6: 4 | P6: P01 | R6: spare | T6: ok
A7: 2 | B7: 6001 | C7: 20U9 | E7: ='Summary Data for Graphics'!C42 -> 6001 | F7: ='Summary Data for Graphics'!D42 -> 88.7 | G7: ='Summary Data for Graphics'!E42 -> 521 | H7: ='Summary Data for Graphics'!F42 -> Good | I7: ='Summary Data for Graphics'!G42 -> 7.7 | J7: ='Summary Data for Graphics'!H42 -> Y | K7: ='Summary Data for Graphics'!I42 -> No | M7: 1 | N7: 3 | P7: P02 | R7: spare | T7: ok
A8: 3 | B8: 3501 | C8: 25S5 | E8: ='Summary Data for Graphics'!C27 -> 3501 | F8: ='Summary Data for Graphics'!D27 -> 15.7 | G8: ='Summary Data for Graphics'!E27 -> 31.5 | H8: ='Summary Data for Graphics'!F27 -> Good | I8: ='Summary Data for Graphics'!G27 -> 0 | J8: ='Summary Data for Graphics'!H27 -> N | K8: ='Summary Data for Graphics'!I27 -> No | M8: 2 | N8: 4 | P8: P03 | R8: 1 | S8: 1 | T8: ok
A9: 4 | B9: 6114 | C9: 20U9 | E9: ='Summary Data for Graphics'!C12 -> 6114 | F9: ='Summary Data for Graphics'!D12 -> 80 | G9: ='Summary Data for Graphics'!E12 -> 220 | H9: ='Summary Data for Graphics'!F12 -> Good | I9: ='Summary Data for Graphics'!G12 -> 7.75 | J9: ='Summary Data for Graphics'!H12 -> Y | K9: ='Summary Data for Graphics'!I12 -> No | M9: 2 | N9: 2 | P9: P04 | R9: 2 | S9: 4 | T9: reduced blocking in forward and reverse directions
A10: 5 | B10: 6294 | C10: 20U9 | E10: ='Summary Data for Graphics'!C26 -> 6294 | F10: ='Summary Data for Graphics'!D26 -> 29.3 | G10: ='Summary Data for Graphics'!E26 -> 162 | H10: ='Summary Data for Graphics'!F26 -> Good | I10: ='Summary Data for Graphics'!G26 -> 0 | J10: ='Summary Data for Graphics'!H26 -> N | K10: ='Summary Data for Graphics'!I26 -> No | M10: 2 | N10: 4 | P10: P05 | Q10: 6001 | R10: 1 | S10: 3 | T10: ok
A11: 6 | B11: 2429 | C11: 13R2 | E11: ='Summary Data for Graphics'!C32 -> 2429 | F11: ='Summary Data for Graphics'!D32 -> 99.3 | G11: ='Summary Data for Graphics'!E32 -> 276.5 | H11: ='Summary Data for Graphics'!F32 -> Good | I11: ='Summary Data for Graphics'!G32 -> 7.4 | J11: ='Summary Data for Graphics'!H32 -> Y | K11: ='Summary Data for Graphics'!I32 -> No | M11: 1 | N11: 1 | P11: P06 | R11: 2 | S11: 2 | T11: shorted forward, reduced blocking reversed
A12: 7 | B12: 2319 | C12: ? | E12: ='Summary Data for Graphics'!C30 -> 2319 | F12: ='Summary Data for Graphics'!D30 -> 20.5 | G12: ='Summary Data for Graphics'!E30 -> 43 | H12: ='Summary Data for Graphics'!F30 -> Good | I12: ='Summary Data for Graphics'!G30 -> 0 | J12: ='Summary Data for Graphics'!H30 -> N | K12: ='Summary Data for Graphics'!I30 -> No | M12: 1 | N12: 1 | P12: P07 | R12: 2 | S12: 2 | T12: ok
A13: 8 | B13: 6219 | C13: 20U9 | E13: ='Summary Data for Graphics'!C10 -> 6219 | F13: ='Summary Data for Graphics'!D10 -> 51 | G13: ='Summary Data for Graphics'!E10 -> 416 | H13: ='Summary Data for Graphics'!F10 -> Good | I13: ='Summary Data for Graphics'!G10 -> 0 | J13: ='Summary Data for Graphics'!H10 -> N | K13: ='Summary Data for Graphics'!I10 -> No | M13: 2 | N13: 2 | P13: P08 | R13: 2 | S13: 2 | T13: ok
A14: 9 | B14: 6272 | C14: 20U9 | E14: ='Summary Data for Graphics'!C11 -> 6272 | F14: ='Summary Data for Graphics'!D11 -> 92 | G14: ='Summary Data for Graphics'!E11 -> 279 | H14: ='Summary Data for Graphics'!F11 -> Good | I14: ='Summary Data for Graphics'!G11 -> 7.72 | J14: ='Summary Data for Graphics'!H11 -> Y | K14: ='Summary Data for Graphics'!I11 -> No | M14: 2 | N14: 2 | P14: P09 | Q14: 2969 | R14: 1 | S14: 4 | T14: forward blocking peculiarity at 2000 V
A15: 10 | B15: 2326 | C15: ? | E15: ='Summary Data for Graphics'!C28 -> 2326 | F15: ='Summary Data for Graphics'!D28 -> 154.2 | G15: ='Summary Data for Graphics'!E28 -> 495 | H15: ='Summary Data for Graphics'!F28 -> Good | I15: ='Summary Data for Graphics'!G28 -> 7.35 | J15: ='Summary Data for Graphics'!H28 -> Y | K15: ='Summary Data for Graphics'!I28 -> No | M15: 1 | N15: 1 | P15: P10 | R15: 2 | S15: 4 | T15: reduced blocking in forward and reverse directions
A16: 11 | B16: 6225 | C16: 20U9 | P16: P11 | R16: 1 | S16: 1 | T16: reduced blocking in forward and reverse directions
A17: 12 | B17: 6223 | C17: 20U9 | P17: P12 | R17: 1 | S17: 1 | T17: ok
A19: SCRs 11 + 12 are tested out of box, but unused in field.

Sheet high-pot results
A1: Spear 2 RF HVPS Hipot Test Results | F1: 16 Aug 2018 + 24 Aug 2018 | N1: Spear 2 RF HVPS Hipot Test Results | S1: 7 Sept. 2018
A10: 43328 | C10: Volts KV | D10: Leakage I | E10: Start/Stop | F10: Resistance | P10: Volts KV | Q10: Leakage I | R10: Start/Stop | S10: Resistance
D11: mA | F11: MΩ | Q11: mA | S11: MΩ
A12: Stage 1 | B12: Begin | C12: 25.5 | D12: 5.2 | E12: 1142 | F12: =C12/D12 -> 4.9038462 | N12: Stage 1 | O12: Begin | P12: 25.5 | Q12: 5.85 | R12: 0940 | S12: =P12/Q12 -> 4.3589744
B13: 10 mins. | C13: 26 | D13: 5.2 | E13: 1152 | F13: =C13/D13 -> 5 | O13: 5 mins. | P13: 25.3 | Q13: 5.82 | R13: 0945 | S13: =P13/Q13 -> 4.347079
A15: Stage 2 | B15: Begin | C15: 25 | D15: 4.6 | E15: 1158 | F15: =C15/D15 -> 5.4347826 | N15: Stage 2 | O15: Begin | P15: 25.2 | Q15: 5.25 | R15: 0954 | S15: =P15/Q15 -> 4.8
B16: 10 mins. | C16: 25.8 | D16: 4.6 | E16: 1208 | F16: =C16/D16 -> 5.6086957 | O16: 5 mins. | P16: 25.1 | Q16: 5.23 | R16: 0959 | S16: =P16/Q16 -> 4.7992352
A18: Stage 3 | B18: Begin | C18: 25 | D18: 6.6 | E18: 1214 | F18: =C18/D18 -> 3.7878788 | N18: Stage 3 | O18: Begin | P18: 25.4 | Q18: 4.33 | R18: 1006 | S18: =P18/Q18 -> 5.8660508
B19: 10 mins. | C19: 25.5 | D19: 6.55 | E19: 1225 | F19: =C19/D19 -> 3.8931298 | O19: 5 mins. | P19: 25.4 | Q19: 4.32 | R19: 1011 | S19: =P19/Q19 -> 5.8796296
A21: Stage 4 | B21: Begin | C21: 16 | D21: 3 | E21: 1227 | F21: =C21/D21 -> 5.3333333 | N21: Stage 4 | O21: Begin | P21: 16.1 | Q21: 3.5 | R21: 1017 | S21: =P21/Q21 -> 4.6
B22: 10 mins. | C22: 16 | D22: 3 | E22: 1237 | F22: =C22/D22 -> 5.3333333 | O22: 5 mins. | P22: 16 | Q22: 3.5 | R22: 1022 | S22: =P22/Q22 -> 4.5714286
A24: Stage 1 to Stage 3: | N24: Stage 1 to Stage 3:
B26: Not performed. | O26: Begin | P26: 80.5 | Q26: 4.85 | R26: 1057 | S26: =P26/Q26 -> 16.597938 | T26: =S12+S15+S18 -> 15.025025
O27: 10 mins. | P27: 80.5 | Q27: 4.7 | R27: 1107 | S27: =P27/Q27 -> 17.12766 | T27: =S13+S16+S19 -> 15.025944
A29: 43336
A30: Stage 1 to Stage 4: | N30: Stage 1 to Stage 4:
B32: Begin | C32: 81.5 | D32: 4.2 | E32: 1120 | F32: =C32/D32 -> 19.404762 | G32: =F12+F15+F18+F21 -> 19.459841 | O32: Begin | P32: 89 | Q32: 4 | R32: 1120 | S32: =P32/Q32 -> 22.25 | T32: =S12+S15+S18+S21 -> 19.625025
B33: 10 mins. | C33: 80.5 | D33: 4.15 | E33: 1130 | F33: =C33/D33 -> 19.39759 | G33: =F13+F16+F19+F22 -> 19.835159 | O33: 10 mins. | P33: 89 | Q33: 4 | R33: 1130 | S33: =P33/Q33 -> 22.25 | T33: =S13+S16+S19+S22 -> 19.597372

Sheet rectifier high-pot results
A1: Test of Spear 2 RF HVPS Main Rectifier Stack #3 vs Spare Main Rectifier Stack
C2: from Building 725
L3: 8 Sept. 2018 | U3: 8 Sept. 2018
A5: Hipot leakage currents stage to stage from August 16, 2018 | J5: Spare Main Rectifier Diode Stack and Filter Box Diode Hipot Tests | S5: Spear 2 RF HVPS Main Rectifier Diode Stack and Filter Box Diode Hipot Tests
C7: Volts KV | D7: Leakage I | E7: Start/Stop | J7: Neg Rail | K7: Volts | L7: Leakage I | M7: Dwell Time | S7: Neg Rail | T7: Volts | U7: Leakage I | V7: Dwell time
D8: mA | F8: MW | K8: KV | L8: mA | N8: MW | T8: KV | U8: mA | W8: MW
A9: Stage 1 | B9: Begin | C9: 25.5 | D9: 5.2 | E9: 1142 | F9: =C9/D9 -> 4.9038462 | J9: A- | K9: 25 | L9: 4.7 | M9: 1 Min. | N9: =K9/L9 -> 5.3191489 | S9: A- | T9: 25 | U9: 7.32 | V9: 1 Min. | W9: =T9/U9 -> 3.4153005
B10: 10 mins. | C10: 26 | D10: 5.2 | E10: 1152 | F10: =C10/D10 -> 5 | J10: B- | K10: 25 | L10: 4.9 | M10: 1 Min. | N10: =K10/L10 -> 5.1020408 | S10: B- | T10: 25 | U10: 8.04 | V10: 1 Min. | W10: =T10/U10 -> 3.1094527
J11: C- | K11: 25 | L11: 4.7 | M11: 1 Min. | N11: =K11/L11 -> 5.3191489 | S11: C- | T11: 25 | U11: 7.38 | V11: 1 Min. | W11: =T11/U11 -> 3.3875339
A12: Stage 2 | B12: Begin | C12: 25 | D12: 4.6 | E12: 1158 | F12: =C12/D12 -> 5.4347826
B13: 10 mins. | C13: 25.8 | D13: 4.6 | E13: 1208 | F13: =C13/D13 -> 5.6086957 | J13: Pos Rail | K13: Volts | L13: Leakage I | M13: Dwell Time | S13: Pos Rail | T13: Volts | U13: Leakage I | V13: Dwell Time
K14: KV | L14: mA | T14: KV | U14: mA
A15: Stage 3 | B15: Begin | C15: 25 | D15: 6.6 | E15: 1214 | F15: =C15/D15 -> 3.7878788 | J15: A+ | K15: 25 | L15: 4.9 | M15: 1 Min. | N15: =K15/L15 -> 5.1020408 | S15: A+ | T15: 25 | U15: 7.45 | V15: 1 Min. | W15: =T15/U15 -> 3.3557047
B16: 10 mins. | C16: 25.5 | D16: 6.55 | E16: 1225 | F16: =C16/D16 -> 3.8931298 | J16: B+ | K16: 25 | L16: 5.3 | M16: 1 Min. | N16: =K16/L16 -> 4.7169811 | S16: B+ | T16: 25 | U16: 7.4 | V16: 1 Min. | W16: =T16/U16 -> 3.3783784
J17: C+ | K17: 25 | L17: 4.9 | M17: 1 Min. | N17: =K17/L17 -> 5.1020408 | S17: C+ | T17: 25 | U17: 7.95 | V17: 1 Min. | W17: =T17/U17 -> 3.1446541
A18: Stage 4 | B18: Begin | C18: 16 | D18: 3 | E18: 1227 | F18: =C18/D18 -> 5.3333333
B19: 10 mins. | C19: 16 | D19: 3 | E19: 1237 | F19: =C19/D19 -> 5.3333333 | K19: Filter Box Diodes, Spare Stack | T19: Filter Box Diodes, #3 Rectifier Stack
J21: Neg Rail | K21: Volts | L21: Leakage I | M21: Dwell Time | S21: Neg Rail | T21: Volts | U21: Leakage I | V21: Dwell Time
K22: KV | L22: uA | N22: MW | T22: KV | U22: uA | W22: MW
J23: A- | K23: 10 | L23: 86 | M23: 1 Min. | N23: =K23/L23*1000 -> 116.27907 | S23: A- | T23: 10 | U23: 82 | V23: 1 Min. | W23: =T23/U23*1000 -> 121.95122
J24: B- | K24: 10 | L24: 85 | M24: 1 Min. | N24: =K24/L24*1000 -> 117.64706 | S24: B- | T24: 10 | U24: 74 | V24: 1 Min. | W24: =T24/U24*1000 -> 135.13514
J25: C- | K25: 10 | L25: 85 | M25: 1 Min. | N25: =K25/L25*1000 -> 117.64706 | S25: C- | T25: 10 | U25: 73 | V25: 1 Min. | W25: =T25/U25*1000 -> 136.9863
J27: Pos Rail | K27: Volts | L27: Leakage I | M27: Dwell Time | S27: Pos Rail | T27: Volts | U27: Leakage I | V27: Dwell Time
K28: KV | L28: uA | T28: KV | U28: uA
J29: A+ | K29: 10 | L29: 95 | M29: 1 Min. | N29: =K29/L29*1000 -> 105.26316 | S29: A+ | T29: 10 | U29: 77.5 | V29: 1 Min. | W29: =T29/U29*1000 -> 129.03226
J30: B+ | K30: 10 | L30: 88 | M30: 1 Min. | N30: =K30/L30*1000 -> 113.63636 | S30: B+ | T30: 10 | U30: 80.2 | V30: 1 Min. | W30: =T30/U30*1000 -> 124.68828
J31: C+ | K31: 10 | L31: 86 | M31: 1 Min. | N31: =K31/L31*1000 -> 116.27907 | S31: C+ | T31: 10 | U31: 81 | V31: 1 Min. | W31: =T31/U31*1000 -> 123.45679

Sheet desy thyristor leakageI
A1: DESY Infineon T1503NH 75T S02
A2: Blocking current (uA) at 4000 VDC 50 degC
A4: Series 1 | B4: Series 2 | C4: Series 3.1 | D4: Series 3.2 | F4: Summary
A5: 400 | B5: 130 | C5: 220 | D5: 230 | F5: =A5 -> 400 | G5: mean | H5: =AVERAGE($F$5:$F$64) -> 225.91667
A6: 300 | B6: 300 | C6: 230 | D6: 230 | F6: =A6 -> 300 | G6: std | H6: =AVEDEV($F$5:$F$64) -> 62.402778
A7: 400 | B7: 280 | C7: 260 | D7: 210 | F7: =A7 -> 400
A8: 200 | B8: 150 | C8: 290 | D8: 225 | F8: =A8 -> 200
A9: 250 | B9: 150 | C9: 375 | D9: 200 | F9: =A9 -> 250
A10: 180 | B10: 100 | C10: 240 | D10: 525 | F10: =A10 -> 180
A11: 205 | B11: 150 | C11: 360 | D11: 140 | F11: =A11 -> 205
A12: 200 | B12: 180 | C12: 250 | D12: 140 | F12: =A12 -> 200
A13: 205 | B13: 450 | C13: 255 | D13: 250 | F13: =A13 -> 205
A14: 200 | B14: 100 | C14: 270 | D14: 150 | F14: =A14 -> 200
A15: 220 | B15: 150 | C15: 270 | D15: 160 | F15: =A15 -> 220
A16: 180 | B16: 120 | C16: 150 | D16: 160 | F16: =A16 -> 180
A17: 160 | B17: 220 | C17: 175 | D17: 320 | F17: =A17 -> 160
A18: 190 | B18: 260 | C18: 175 | D18: 150 | F18: =A18 -> 190
C19: 185 | D19: 295 | F19: =B5 -> 130
C20: 205 | D20: 230 | F20: =B6 -> 300
F21: =B7 -> 280
A22: =AVERAGE(A5:A18) -> 235 | B22: =AVERAGE(B5:B18) -> 195.71429 | C22: =AVERAGE(C5:C20) -> 244.375 | D22: =AVERAGE(D5:D20) -> 225.9375 | F22: =B8 -> 150
A23: =AVEDEV(A5:A18) -> 58.571429 | B23: =AVEDEV(B5:B18) -> 75.918367 | C23: =AVEDEV(C5:C20) -> 46.875 | D23: =AVEDEV(D5:D20) -> 62.304688 | F23: =B9 -> 150
F24: =B10 -> 100
F25: =B11 -> 150
F26: =B12 -> 180
F27: =B13 -> 450
F28: =B14 -> 100
F29: =B15 -> 150
F30: =B16 -> 120
F31: =B17 -> 220
F32: =B18 -> 260
F33: =C5 -> 220
F34: =C6 -> 230
F35: =C7 -> 260
F36: =C8 -> 290
F37: =C9 -> 375
F38: =C10 -> 240
F39: =C11 -> 360
F40: =C12 -> 250
F41: =C13 -> 255
...

Sheet ler 4-4
B1: Leakage Tests of SCRs Removed From LER 4-4 (Sept. 13-14, 2018) + 2 Stacks From Spear 2 (Oct. 26, 2012)
B3: Spear 2 Crowbar Stack removed Oct. 26, 2012 | O3: LER 4-4 Crowbar Stack SCRs removed 13+14 Sept. 2018 | Z3: LER 4-4 and 2012 HVPS2 Crowbar Stack SCRs Summary
B5: Stack 1 | C5: S/N | D5: I @ 4.2 KV | E5: I @ 6.5 KV | F5: F.O. | G5: S. F. KV | H5: Pass? | I5: Creeping Up? | J5: Re-Use? | O5: Stack 1 | P5: S/N | Q5: I @ 4.2 KV | R5: I @ 6.5 KV | S5: F.O. | T5: S. F. KV | U5: Pass? | V5: Creeping Up? | W5: Re-Use?
B6: 1 | C6: 2510 | D6: 8.5 | E6: 19.6 | F6: Good | G6: 6.9 | H6: Y | I6: N | J6: Y | O6: 1 | P6: 5311 | Q6: 7.2 | R6: 21 | S6: Good | T6: 7.1 | U6: Y | V6: N | W6: Y | Z6: =P6 -> 5311 | AA6: =Q6 -> 7.2 | AB6: =R6 -> 21 | AC6: =T6 -> 7.1
B7: 2 | C7: 2491 | D7: 90.4 | E7: 155.3 | F7: Good | G7: 9+ No SF | H7: N | I7: N | J7: N | O7: 2 | P7: 5313 | Q7: 6.7 | R7: 13.2 | S7: Good | T7: 7.1 | U7: Y | V7: N | W7: Y | Z7: =P7 -> 5313 | AA7: =Q7 -> 6.7 | AB7: =R7 -> 13.2 | AC7: =T7 -> 7.1
B8: 3 | C8: 2503 | D8: 6 | E8: 11 | F8: Good | G8: 6.9 | H8: Y | I8: N | J8: Y | O8: 3 | P8: 5312 | Q8: 10.4 | R8: 25.8 | S8: Good | T8: 7 | U8: Y | V8: N | W8: Y | Z8: =P8 -> 5312 | AA8: =Q8 -> 10.4 | AB8: =R8 -> 25.8 | AC8: =T8 -> 7
B9: 4 | C9: 2515 | D9: 30.5 | E9: 53.1 | F9: Good | G9: 6.9 | H9: Y | I9: N | J9: Y | O9: 4 | P9: 5314 | Q9: 6 | R9: 10.2 | S9: Good | T9: 7.1 | U9: Y | V9: N | W9: Y | Z9: =P9 -> 5314 | AA9: =Q9 -> 6 | AB9: =R9 -> 10.2 | AC9: =T9 -> 7.1
B10: 5 | C10: 2511 | D10: 14.7 | E10: 38.8 | F10: Good | G10: 7 | H10: Y | I10: N | J10: Y | O10: 5 | P10: 5392 | Q10: 9.5 | R10: 31 | S10: Good | T10: 7 | U10: Y | V10: N | W10: Y | Z10: =P10 -> 5392 | AA10: =Q10 -> 9.5 | AB10: =R10 -> 31 | AC10: =T10 -> 7
B11: 6 | C11: 2335 | D11: 35 | E11: 98.5 | F11: Good | G11: 6.9 | H11: Y | I11: N | J11: Y | O11: 6 | P11: 5393 | Q11: 14.4 | R11: 42.2 | S11: Good | T11: 7 | U11: Y | V11: N | W11: Y | Z11: =P11 -> 5393 | AA11: =Q11 -> 14.4 | AB11: =R11 -> 42.2 | AC11: =T11 -> 7
Z12: =P15 -> 5328 | AA12: =Q15 -> 7 | AB12: =R15 -> 16 | AC12: =T15 -> 7
Z13: =P16 -> 5330 | AA13: =Q16 -> 12.5 | AB13: =R16 -> 27.2 | AC13: =T16 -> 7
B14: Stack 2 | C14: S/N | D14: I @ 4.2 KV | E14: I @ 6.5 KV | F14: F.O. | G14: S. F. KV | H14: Pass? | J14: Re-Use? | O14: Stack 2 | P14: S/N | Q14: I @ 4.2 KV | R14: I @ 6.5 KV | S14: F.O. | T14: S. F. KV | U14: Pass? | W14: Re-Use? | Z14: =P17 -> 5331 | AA14: =Q17 -> 18 | AB14: =R17 -> 38.8 | AC14: =T17 -> 7.3
B15: 1 | C15: 3503 | D15: 24.6 | E15: 38.2 | F15: Good | G15: 6.85 | H15: Y | I15: N | J15: Y | O15: 1 | P15: 5328 | Q15: 7 | R15: 16 | S15: Good | T15: 7 | U15: Y | V15: N | W15: Y | Z15: =P18 -> 5329 | AA15: =Q18 -> 46.7 | AB15: =R18 -> 98.5 | AC15: =T18 -> 7
B16: 2 | C16: 3500 | D16: 28.9 | E16: 47.2 | F16: Good | G16: 7.1 | H16: Y | I16: N | J16: Y | O16: 2 | P16: 5330 | Q16: 12.5 | R16: 27.2 | S16: Good | T16: 7 | U16: Y | V16: N | W16: Y | Z16: =P19 -> 5386 | AA16: =Q19 -> 31.5 | AB16: =R19 -> 198 | AC16: =T19 -> 6.85
B17: 3 | C17: 3528 | D17: 76.8+ | E17: 113+ | F17: Good | G17: 7 | H17: Marg. | I17: Y | J17: N | O17: 3 | P17: 5331 | Q17: 18 | R17: 38.8 | S17: Good | T17: 7.3 | U17: Y | V17: N | W17: Y | Z17: =P20 -> 5387 | AA17: =Q20 -> 20.3 | AB17: =R20 -> 84 | AC17: =T20 -> 6.95
B18: 4 | C18: 3461 | D18: 1268+ | E18: 4000+ | F18: Good | G18: Short SF | H18: N | I18: Y | J18: N | O18: 4 | P18: 5329 | Q18: 46.7 | R18: 98.5 | S18: Good | T18: 7 | U18: Marg. | V18: Y | W18: N | Z18: =P24 -> 5409 | AA18: =Q24 -> 61.7 | AB18: =R24 -> 208.3 | AC18: =T24 -> 7
B19: 5 | C19: 3523 | D19: 87.5+ | E19: 875+ | F19: Good | G19: 6.8 | H19: Marg. | I19: Y | J19: N | O19: 5 | P19: 5386 | Q19: 31.5 | R19: 198 | S19: Good | T19: 6.85 | U19: Y | V19: N | W19: Y | Z19: =P25 -> 5410 | AA19: =Q25 -> 11.4 | AB19: =R25 -> 20.2 | AC19: =T25 -> 7.1
B20: 6 | C20: 3504 | D20: 12.2 | E20: 21.9 | F20: Good | G20: 6.8 | H20: Y | I20: N | J20: Y | O20: 6 | P20: 5387 | Q20: 20.3 | R20: 84 | S20: Good | T20: 6.95 | U20: Marg. | V20: Y | W20: N | Z20: =P26 -> 5241 | AA20: =Q26 -> 10.9 | AB20: =R26 -> 23.6 | AC20: =T26 -> 7.1
Z21: =P27 -> 5161 | AA21: =Q27 -> 202.5 | AB21: =R27 -> 334 | AC21: =T27 -> 7
Z22: =P28 -> 5154 | AA22: =Q28 -> 990 | AB22: =R28 -> 3100 | AC22: =T28 -> 7.1
O23: Stack 3 | P23: S/N | Q23: I @ 4.2 KV | R23: I @ 6.5 KV | S23: F.O. | T23: S. F. KV | U23: Pass? | W23: Re-Use? | Z23: =P29 -> 5244 | AA23: =Q29 -> 43 | AB23: =R29 -> 163 | AC23: =T29 -> 7.7
O24: 1 | P24: 5409 | Q24: 61.7 | R24: 208.3 | S24: Good | T24: 7 | U24: Marg. | V24: N | W24: N | Z24: =P33 -> 5255 | AA24: =Q33 -> 14 | AB24: =R33 -> 45.6 | AC24: =T33 -> 7.6
B25: Note 1: all currents listed on this sheet are in microamps (uA). | O25: 2 | P25: 5410 | Q25: 11.4 | R25: 20.2 | S25: Good | T25: 7.1 | U25: Y | V25: N | W25: Y | Z25: =P34 -> 5407 | AA25: =Q34 -> 19.2 | AB25: =R34 -> 41.8 | AC25: =T34 -> 7
O26: 3 | P26: 5241 | Q26: 10.9 | R26: 23.6 | S26: Good | T26: 7.1 | U26: Y | V26: N | W26: Y | Z26: =P35 -> 5253 | AA26: =Q35 -> 21.9 | AB26: =R35 -> 41.7 | AC26: =T35 -> 7
B27: Note 2: "+" symbol after a leakage current number denotes creeping current. | O27: 4 | P27: 5161 | Q27: 202.5 | R27: 334 | S27: Good | T27: 7 | U27: Marg. | V27: Y | W27: N | Z27: =P36 -> 3634 | AA27: =Q36 -> 920 | AB27: =R36 -> 2700 | AC27: =T36 -> 7
O28: 5 | P28: 5154 | Q28: 990 | R28: 3100 | S28: Good | T28: 7.1 | U28: N | V28: Y | W28: N | Z28: =P37 -> 5388 | AA28: =Q37 -> 20.7 | AB28: =R37 -> 37 | AC28: =T37 -> 7
O29: 6 | P29: 5244 | Q29: 43 | R29: 163 | S29: Good | T29: 7.7 | U29: Marg. | V29: Y | W29: N | Z29: =P38 -> 5389 | AA29: =Q38 -> 25 | AB29: =R38 -> 124.5 | AC29: =T38 -> 7
Z30: 2510 | AA30: 8.5 | AB30: 19.6
Z31: 2491 | AA31: 90.4 | AB31: 155.3
O32: Stack 4 | P32: S/N | Q32: I @ 4.2 KV | R32: I @ 6.5 KV | S32: F.O. | T32: S. F. KV | U32: Pass? | W32: Re-Use? | Z32: 2503 | AA32: 6 | AB32: 11
O33: 1 | P33: 5255 | Q33: 14 | R33: 45.6 | S33: Good | T33: 7.6 | U33: Y | V33: N | W33: Y | Z33: 2515 | AA33: 30.5 | AB33: 53.1
O34: 2 | P34: 5407 | Q34: 19.2 | R34: 41.8 | S34: Good | T34: 7 | U34: Y | V34: N | W34: Y | Z34: 2511 | AA34: 14.7 | AB34: 38.8
O35: 3 | P35: 5253 | Q35: 21.9 | R35: 41.7 | S35: Good | T35: 7 | U35: Y | V35: N | W35: Y | Z35: 2335 | AA35: 35 | AB35: 98.5
O36: 4 | P36: 3634 | Q36: 920 | R36: 2700 | S36: Good | T36: 7 | U36: N | V36: N | W36: N | Z36: 3503 | AA36: 24.6 | AB36: 38.2
O37: 5 | P37: 5388 | Q37: 20.7 | R37: 37 | S37: Good | T37: 7 | U37: Y | V37: N | W37: Y | Z37: 3500 | AA37: 28.9 | AB37: 47.2
O38: 6 | P38: 5389 | Q38: 25 | R38: 124.5 | S38: Good | T38: 7 | U38: Y | V38: N | W38: Y | Z38: 3528 | AA38: 76.8 | AB38: 113
Z39: 3461 | AA39: 1268 | AB39: 4000
Z40: 3523 | AA40: 87.5 | AB40: 875
Z41: 3504 | AA41: 12.2 | AB41: 21.9
B44: LER 4-4 Phase Stack SCRs removed 13+14 Sept. 2018 | AG44: LER 4-4 Phase Tank Stacks
...

Sheet spare stacks
A1: New Spare Crowbar Stacks for Spear 1+2.
A3: SCRs are from LER 4-4 which were removed 14 Sept. 2018
D5: Set 1 | E5: Date: Oct 2, 2018 | M5: Set 2 | N5: Date: Oct 6, 2018
B7: Stack 1 | C7: SCR S/N | D7: Stack Leakage @ 25 KVDC | E7: Fiber Optic Trig Test | F7: SF KV | G7: Pass/Fail | H7: uA @ 4.2 kV | K7: Stack 1 | L7: SCR S/N | M7: Stack Leakage @ 25 KVDC | N7: Fiber Optic Trig Test | O7: SF KV | P7: Pass/Fail | Q7: uA @ 4.2 kV
B8: Cell 1 | C8: 5389 | H8: 25 | K8: Cell 1 | L8: 5289 | Q8: 5
B9: Cell 2 | C9: 5281 | H9: 19 | K9: Cell 2 | L9: 5270 | Q9: 6.2
B10: Cell 3 | C10: 5311 | D10: .850 mA | E10: Good | F10: 40.56 | G10: Pass | H10: 7.2 | K10: Cell 3 | L10: 5424 | M10: .841 mA | N10: Good | O10: 40.05 | P10: Pass | Q10: 7.2
B11: Cell 4 | C11: 2335 | H11: 35 | K11: Cell 4 | L11: 5336 | Q11: 6.4
B12: Cell 5 | C12: 5240 | H12: 8.4 | K12: Cell 5 | L12: 5385 | Q12: 10.8
B13: Cell 6 | C13: 5304 | H13: 7 | K13: Cell 6 | L13: 5383 | Q13: 8.8
B15: Stack 2 | K15: Stack 2
B16: Cell 1 | C16: 5307 | H16: 11.4 | K16: Cell 1 | L16: 5343 | Q16: 4.4
B17: Cell 2 | C17: 5393 | H17: 14.4 | K17: Cell 2 | L17: 5186 | Q17: 6.4
B18: Cell 3 | C18: 5288 | D18: .855 mA | E18: Good | F18: 41.07 | G18: Pass | H18: 20 | K18: Cell 3 | L18: 5317 | M18: .836 mA | N18: Good | O18: 40.04 | P18: Pass | Q18: 5.9
B19: Cell 4 | C19: 2503 | H19: 6 | K19: Cell 4 | L19: 5303 | Q19: 9.9
B20: Cell 5 | C20: 2511 | H20: 14.7 | K20: Cell 5 | L20: 5337 | Q20: 6.2
B21: Cell 6 | C21: 5309 | H21: 11.4 | K21: Cell 6 | L21: 5382 | Q21: 4.9
B23: Stack 3 | K23: Stack 3
B24: Cell 1 | C24: 5283 | H24: 6.3 | K24: Cell 1 | L24: 5290 | Q24: 4.5
B25: Cell 2 | C25: 5330 | H25: 12.5 | K25: Cell 2 | L25: 5297 | Q25: 7
B26: Cell 3 | C26: 5295 | D26: .857 mA | E26: Good | F26: 41.08 | G26: Pass | H26: 31.7 | K26: Cell 3 | L26: 5423 | M26: .837 mA | N26: Good | O26: 40 | P26: Pass | Q26: ?
B27: Cell 4 | C27: 5238 | H27: 4 | K27: Cell 4 | L27: 5384 | Q27: 9.5
B28: Cell 5 | C28: 5269 | H28: 25.8 | K28: Cell 5 | L28: 5236 | Q28: 5.6
B29: Cell 6 | C29: 5255 | H29: 14 | K29: Cell 6 | L29: 5249 | Q29: 4.7
B31: Stack 4 | K31: Stack 4
B32: Cell 1 | C32: 5314 | H32: 6 | K32: Cell 1 | L32: 5339 | Q32: 5.3
B33: Cell 2 | C33: 5392 | H33: 9.5 | K33: Cell 2 | L33: 5296 | Q33: 6.8
B34: Cell 3 | C34: 5331 | D34: .856 mA | E34: Good | F34: 41.21 | G34: Pass | H34: 18 | K34: Cell 3 | L34: 5341 | M34: .836 mA | N34: Good | O34: 40.34 | P34: Pass | Q34: 6.5
B35: Cell 4 | C35: 5407 | H35: 19.2 | K35: Cell 4 | L35: 5340 | Q35: 7.1
B36: Cell 5 | C36: 2510 | H36: 8.5 | K36: Cell 5 | L36: 5275 | Q36: 4.5
B37: Cell 6 | C37: 5239 | H37: 6.1 | K37: Cell 6 | L37: 5342 | Q37: 4.9

Sheet HVPS1 stacks 20190226
F2: Cold Tests @ 22 deg. C | R2: Hot Tests @ approx. 50 deg. C | W2: HVPS1 Stack Summary
W3: Cold Tests | Y3: Hot Tests
B4: Stack 1 | C4: SCR # | D4: Serial # | E4: Date Code | F4: uA @ 4.2 KV | G4: uA @ 6.5KV | H4: F.O. Trigs | I4: OV Self-Fire | J4: Re-Use? | N4: Stack 1 | O4: SCR # | P4: Serial # | Q4: Date Code | R4: uA @ 4.2 KV | S4: uA @ 6.5KV | T4: AnodeTemp | V4: Serial No. | W4: 4.2 kV | X4: 6.5 kV | Y4: 4.2 kV | Z4: 6.5 kV
C5: 1 | D5: 3506 | E5: 20S4 | F5: 20.8 | G5: 33.94 | H5: G | I5: 7.32 | J5: Y | O5: 1 | P5: 3506 | Q5: 20S4 | R5: 133.7+ | S5: 226.5+ | T5: 50.35 | V5: 3506 | W5: 20.8 | X5: 33.94 | Y5: 133.7 | Z5: 226.5
C6: 2 | D6: 3006 | E6: 02S4 | F6: 13.6 | G6: 26.2 | H6: G | I6: 7.24 | J6: Y | O6: 2 | P6: 3006 | Q6: 02S4 | R6: 220.5+ | S6: 375+ | T6: 50.75 | V6: 3006 | W6: 13.6 | X6: 26.2 | Y6: 220.5 | Z6: 375
C7: 3 | D7: 3205 | E7: 02S4 | F7: 34 | G7: 65 | H7: G | I7: 7.2 | J7: Y | O7: 3 | P7: 3205 | Q7: 02S4 | R7: 319+ | S7: 586+ | T7: 51.25 | V7: 3205 | W7: 34 | X7: 65 | Y7: 319 | Z7: 586
C8: 4 | D8: 3290 | E8: 25S5 | F8: 28.4 | G8: 68.4 | H8: G | I8: 7.4 | J8: Y | O8: 4 | P8: 3290 | Q8: 25S5 | R8: 146.5+ | S8: 322.2+ | T8: 51.3 | V8: 3290 | W8: 28.4 | X8: 68.4 | Y8: 146.5 | Z8: 322.2
C9: 5 | D9: 3170 | E9: 02S4 | F9: 3.1 | G9: 5.1 | H9: G | I9: 7.12 | J9: Y | O9: 5 | P9: 3170 | Q9: 02S4 | R9: 52.1+ | S9: 101.1+ | T9: 51.8 | V9: 3170 | W9: 3.1 | X9: 5.1 | Y9: 52.1 | Z9: 101.1
C10: 6 | D10: 3209 | E10: 02S4 | F10: 38.1 | G10: 73.3 | H10: G | I10: 7.84 | J10: Y | O10: 6 | P10: 3209 | Q10: 02S4 | R10: 344+ | S10: 609+ | T10: 50.55 | V10: 3209 | W10: 38.1 | X10: 73.3 | Y10: 344 | Z10: 609
V11: 2502 | W11: 13.6 | X11: 27.9 | Y11: 91.2 | Z11: 182.6
